2024-05-19 20:14:14,054 - INFO - logging in using static token
2024-05-19 20:14:16,121 - INFO - Shard ID None has connected to Gateway (Session ID: f3b16ceb7f1fecb7d36550abaf6417b2).
2024-05-19 20:17:40,582 - INFO - logging in using static token
2024-05-19 20:17:42,636 - INFO - Shard ID None has connected to Gateway (Session ID: 686c53dada1ae8b5f0e307e282e69130).
2024-05-19 20:18:25,040 - INFO - logging in using static token
2024-05-19 20:18:26,702 - INFO - Shard ID None has connected to Gateway (Session ID: 05e8750aac3e24876fb2eab9229d1b2b).
2024-05-19 20:19:00,947 - INFO - logging in using static token
2024-05-19 20:19:02,971 - INFO - Shard ID None has connected to Gateway (Session ID: fa27e2818ea1808142b410910988afd2).
2024-05-19 20:19:57,448 - INFO - logging in using static token
2024-05-19 20:19:59,251 - INFO - Shard ID None has connected to Gateway (Session ID: 1637cde477bd227dfe918f6aac528918).
2024-05-19 21:14:42,860 - INFO - logging in using static token
2024-05-19 21:14:44,967 - INFO - Shard ID None has connected to Gateway (Session ID: 9fff6076e68e17499aa688b76483f76d).
2024-05-19 21:16:03,984 - INFO - logging in using static token
2024-05-19 21:16:05,724 - INFO - Shard ID None has connected to Gateway (Session ID: 2cf4b79ef4613f1f9db59870e49c22c6).
2024-05-19 21:17:52,941 - INFO - logging in using static token
2024-05-19 21:17:54,574 - INFO - Shard ID None has connected to Gateway (Session ID: 6a320a08a8105d850f54fbf1fc6f30a7).
2024-05-19 21:19:18,350 - INFO - logging in using static token
2024-05-19 21:19:20,009 - INFO - Shard ID None has connected to Gateway (Session ID: d91301c3ab9f19322270e2228670db4a).
2024-05-19 21:19:48,660 - INFO - logging in using static token
2024-05-19 21:19:50,434 - INFO - Shard ID None has connected to Gateway (Session ID: 18bd71272c5dc2c456617fe2cb94461c).
2024-05-19 21:20:17,319 - ERROR - Ignoring exception in command None
discord.ext.commands.errors.CommandNotFound: Command "call" is not found
2024-05-19 21:20:47,863 - INFO - logging in using static token
2024-05-19 21:20:50,048 - INFO - Shard ID None has connected to Gateway (Session ID: d26af1c9179f9c1d6f0c0d17e433a568).
2024-05-19 21:21:14,522 - ERROR - Ignoring exception in command schedule
Traceback (most recent call last):
  File "/Users/manideepghanta/Downloads/Discord_Bot/discord_bot/lib/python3.12/site-packages/discord/ext/commands/bot.py", line 1350, in invoke
    await ctx.command.invoke(ctx)
  File "/Users/manideepghanta/Downloads/Discord_Bot/discord_bot/lib/python3.12/site-packages/discord/ext/commands/core.py", line 1021, in invoke
    await self.prepare(ctx)
  File "/Users/manideepghanta/Downloads/Discord_Bot/discord_bot/lib/python3.12/site-packages/discord/ext/commands/core.py", line 938, in prepare
    await self._parse_arguments(ctx)
  File "/Users/manideepghanta/Downloads/Discord_Bot/discord_bot/lib/python3.12/site-packages/discord/ext/commands/hybrid.py", line 531, in _parse_arguments
    return await super()._parse_arguments(ctx)
           ^^^^^^^^^^^^^^^^^^^^^^^^^^^^^^^^^^^
  File "/Users/manideepghanta/Downloads/Discord_Bot/discord_bot/lib/python3.12/site-packages/discord/ext/commands/core.py", line 845, in _parse_arguments
    transformed = await self.transform(ctx, param, attachments)
                  ^^^^^^^^^^^^^^^^^^^^^^^^^^^^^^^^^^^^^^^^^^^^^
  File "/Users/manideepghanta/Downloads/Discord_Bot/discord_bot/lib/python3.12/site-packages/discord/ext/commands/core.py", line 715, in transform
    return await run_converters(ctx, converter, argument, param)  # type: ignore
           ^^^^^^^^^^^^^^^^^^^^^^^^^^^^^^^^^^^^^^^^^^^^^^^^^^^^^
  File "/Users/manideepghanta/Downloads/Discord_Bot/discord_bot/lib/python3.12/site-packages/discord/ext/commands/converter.py", line 1346, in run_converters
    raise BadLiteralArgument(param, literal_args, errors, argument)
discord.ext.commands.errors.BadLiteralArgument: Could not convert "day" into the literal 'Sat', 'Sun', 'Mon', 'Tue', 'Wed', 'Thur', or 'Fri'.
2024-05-19 21:21:32,123 - ERROR - Ignoring exception in command None
discord.ext.commands.errors.CommandNotFound: Command "scheduel" is not found
2024-05-19 21:25:57,127 - INFO - logging in using static token
2024-05-19 21:25:59,100 - INFO - Shard ID None has connected to Gateway (Session ID: 8dd76e875b0d39b13fb78b98ef7967b4).
2024-05-19 21:26:42,656 - INFO - logging in using static token
2024-05-19 21:26:44,675 - INFO - Shard ID None has connected to Gateway (Session ID: eda00426657696c9f85462683f3d3a53).
2024-05-19 21:26:49,646 - WARNING - We are being rate limited. PUT https://discord.com/api/v10/applications/1232033554972676148/commands responded with 429. Retrying in 11.89 seconds.
2024-05-19 21:29:10,529 - INFO - logging in using static token
2024-05-19 21:29:12,600 - INFO - Shard ID None has connected to Gateway (Session ID: 00358270bd2c1c6f6c65739fd6a56563).
2024-05-19 21:30:15,503 - INFO - logging in using static token
2024-05-19 21:30:17,290 - INFO - Shard ID None has connected to Gateway (Session ID: baee7e6951034286f5e1b3b32f70f8cb).
2024-05-19 21:30:46,093 - ERROR - Unhandled exception in internal background task 'check_time'.
Traceback (most recent call last):
  File "/Users/manideepghanta/Downloads/Discord_Bot/discord_bot/lib/python3.12/site-packages/discord/ext/tasks/__init__.py", line 239, in _loop
    await self.coro(*args, **kwargs)
  File "/Users/manideepghanta/Downloads/Discord_Bot/main.py", line 64, in check_time
    await channel.send("@everyone, Let's Check in!")
  File "/Users/manideepghanta/Downloads/Discord_Bot/discord_bot/lib/python3.12/site-packages/discord/ext/commands/context.py", line 1060, in send
    await self.interaction.response.send_message(**kwargs)
  File "/Users/manideepghanta/Downloads/Discord_Bot/discord_bot/lib/python3.12/site-packages/discord/interactions.py", line 801, in send_message
    await adapter.create_interaction_response(
  File "/Users/manideepghanta/Downloads/Discord_Bot/discord_bot/lib/python3.12/site-packages/discord/webhook/async_.py", line 221, in request
    raise HTTPException(response, data)
discord.errors.HTTPException: 400 Bad Request (error code: 40060): Interaction has already been acknowledged.
2024-05-19 21:32:15,127 - ERROR - Task exception was never retrieved
future: <Task finished name='Task-8' coro=<Loop._loop() done, defined at /Users/manideepghanta/Downloads/Discord_Bot/discord_bot/lib/python3.12/site-packages/discord/ext/tasks/__init__.py:200> exception=HTTPException('400 Bad Request (error code: 40060): Interaction has already been acknowledged.')>
Traceback (most recent call last):
  File "/Users/manideepghanta/Downloads/Discord_Bot/discord_bot/lib/python3.12/site-packages/discord/ext/tasks/__init__.py", line 264, in _loop
    raise exc
  File "/Users/manideepghanta/Downloads/Discord_Bot/discord_bot/lib/python3.12/site-packages/discord/ext/tasks/__init__.py", line 239, in _loop
    await self.coro(*args, **kwargs)
  File "/Users/manideepghanta/Downloads/Discord_Bot/main.py", line 64, in check_time
  File "/Users/manideepghanta/Downloads/Discord_Bot/discord_bot/lib/python3.12/site-packages/discord/ext/commands/context.py", line 1060, in send
    await self.interaction.response.send_message(**kwargs)
  File "/Users/manideepghanta/Downloads/Discord_Bot/discord_bot/lib/python3.12/site-packages/discord/interactions.py", line 801, in send_message
    await adapter.create_interaction_response(
  File "/Users/manideepghanta/Downloads/Discord_Bot/discord_bot/lib/python3.12/site-packages/discord/webhook/async_.py", line 221, in request
    raise HTTPException(response, data)
discord.errors.HTTPException: 400 Bad Request (error code: 40060): Interaction has already been acknowledged.
2024-05-19 21:33:00,289 - INFO - logging in using static token
2024-05-19 21:33:02,078 - INFO - Shard ID None has connected to Gateway (Session ID: aca3438417bddf949adca1c5c4a31b42).
2024-05-19 22:00:12,654 - INFO - logging in using static token
2024-05-19 22:00:14,562 - INFO - Shard ID None has connected to Gateway (Session ID: 4f8095a4b352752b656efcc7df643670).
2024-05-19 22:01:27,745 - INFO - logging in using static token
2024-05-19 22:01:29,365 - INFO - Shard ID None has connected to Gateway (Session ID: df85dc79667dd670aee9cbe160e70841).
2024-05-19 22:01:43,272 - ERROR - Ignoring exception in command say
Traceback (most recent call last):
  File "/Users/manideepghanta/Downloads/Discord_Bot/discord_bot/lib/python3.12/site-packages/discord/ext/commands/core.py", line 235, in wrapped
    ret = await coro(*args, **kwargs)
          ^^^^^^^^^^^^^^^^^^^^^^^^^^^
  File "/Users/manideepghanta/Downloads/Discord_Bot/main.py", line 54, in say
    chan = ctx.get_channel(1018200114059280417)
           ^^^^^^^^^^^^^^^
AttributeError: 'Context' object has no attribute 'get_channel'. Did you mean: '_get_channel'?

The above exception was the direct cause of the following exception:

Traceback (most recent call last):
  File "/Users/manideepghanta/Downloads/Discord_Bot/discord_bot/lib/python3.12/site-packages/discord/ext/commands/bot.py", line 1350, in invoke
    await ctx.command.invoke(ctx)
  File "/Users/manideepghanta/Downloads/Discord_Bot/discord_bot/lib/python3.12/site-packages/discord/ext/commands/core.py", line 1029, in invoke
    await injected(*ctx.args, **ctx.kwargs)  # type: ignore
    ^^^^^^^^^^^^^^^^^^^^^^^^^^^^^^^^^^^^^^^
  File "/Users/manideepghanta/Downloads/Discord_Bot/discord_bot/lib/python3.12/site-packages/discord/ext/commands/core.py", line 244, in wrapped
    raise CommandInvokeError(exc) from exc
discord.ext.commands.errors.CommandInvokeError: Command raised an exception: AttributeError: 'Context' object has no attribute 'get_channel'
2024-05-19 22:01:59,343 - INFO - logging in using static token
2024-05-19 22:02:02,239 - INFO - Shard ID None has connected to Gateway (Session ID: a9f595a8bc5c879880947a43381d3832).
2024-05-19 22:02:45,042 - INFO - logging in using static token
2024-05-19 22:02:46,974 - INFO - Shard ID None has connected to Gateway (Session ID: 849a9fcf50b71f868330eca8f6021c1e).
2024-05-19 22:24:21,883 - INFO - Shard ID None has successfully RESUMED session 849a9fcf50b71f868330eca8f6021c1e.
2024-05-19 23:12:26,625 - INFO - logging in using static token
2024-05-19 23:12:28,637 - INFO - Shard ID None has connected to Gateway (Session ID: 01ae1bfed7d99a50f17381cfabd693aa).
2024-05-19 23:12:48,788 - ERROR - Ignoring exception in command pass_me_butter
Traceback (most recent call last):
  File "/Users/manideepghanta/Downloads/Discord_Bot/discord_bot/lib/python3.12/site-packages/discord/ext/commands/core.py", line 235, in wrapped
    ret = await coro(*args, **kwargs)
          ^^^^^^^^^^^^^^^^^^^^^^^^^^^
  File "/Users/manideepghanta/Downloads/Discord_Bot/main.py", line 65, in pass_me_butter
    await ctx.send(content="Here's you butter", embed=Embed(type='rich',description="Placeholder", url='assets/images/butter.png'))
  File "/Users/manideepghanta/Downloads/Discord_Bot/discord_bot/lib/python3.12/site-packages/discord/ext/commands/context.py", line 1024, in send
    return await super().send(
           ^^^^^^^^^^^^^^^^^^^
  File "/Users/manideepghanta/Downloads/Discord_Bot/discord_bot/lib/python3.12/site-packages/discord/abc.py", line 1561, in send
    data = await state.http.send_message(channel.id, params=params)
           ^^^^^^^^^^^^^^^^^^^^^^^^^^^^^^^^^^^^^^^^^^^^^^^^^^^^^^^^
  File "/Users/manideepghanta/Downloads/Discord_Bot/discord_bot/lib/python3.12/site-packages/discord/http.py", line 745, in request
    raise HTTPException(response, data)
discord.errors.HTTPException: 400 Bad Request (error code: 50035): Invalid Form Body
In embeds.0.url: Scheme "assets/images/butter.png" is not supported. Scheme must be one of ('http', 'https'). Not a well formed URL.

The above exception was the direct cause of the following exception:

Traceback (most recent call last):
  File "/Users/manideepghanta/Downloads/Discord_Bot/discord_bot/lib/python3.12/site-packages/discord/ext/commands/bot.py", line 1350, in invoke
    await ctx.command.invoke(ctx)
  File "/Users/manideepghanta/Downloads/Discord_Bot/discord_bot/lib/python3.12/site-packages/discord/ext/commands/core.py", line 1029, in invoke
    await injected(*ctx.args, **ctx.kwargs)  # type: ignore
    ^^^^^^^^^^^^^^^^^^^^^^^^^^^^^^^^^^^^^^^
  File "/Users/manideepghanta/Downloads/Discord_Bot/discord_bot/lib/python3.12/site-packages/discord/ext/commands/core.py", line 244, in wrapped
    raise CommandInvokeError(exc) from exc
discord.ext.commands.errors.CommandInvokeError: Command raised an exception: HTTPException: 400 Bad Request (error code: 50035): Invalid Form Body
In embeds.0.url: Scheme "assets/images/butter.png" is not supported. Scheme must be one of ('http', 'https'). Not a well formed URL.
2024-05-19 23:14:02,142 - INFO - logging in using static token
2024-05-19 23:14:03,879 - INFO - Shard ID None has connected to Gateway (Session ID: 650b57e5cc155fa020d014b57503a939).
2024-05-19 23:14:09,494 - ERROR - Ignoring exception in command pass_me_butter
Traceback (most recent call last):
  File "/Users/manideepghanta/Downloads/Discord_Bot/discord_bot/lib/python3.12/site-packages/discord/ext/commands/core.py", line 235, in wrapped
    ret = await coro(*args, **kwargs)
          ^^^^^^^^^^^^^^^^^^^^^^^^^^^
  File "/Users/manideepghanta/Downloads/Discord_Bot/main.py", line 65, in pass_me_butter
    await ctx.send(content="Here's you butter", embed=Embed(type='rich',description="Placeholder", file=File('assets/images/butter.png')))
                                                      ^^^^^^^^^^^^^^^^^^^^^^^^^^^^^^^^^^^^^^^^^^^^^^^^^^^^^^^^^^^^^^^^^^^^^^^^^^^^^^^^^^^
TypeError: Embed.__init__() got an unexpected keyword argument 'file'

The above exception was the direct cause of the following exception:

Traceback (most recent call last):
  File "/Users/manideepghanta/Downloads/Discord_Bot/discord_bot/lib/python3.12/site-packages/discord/ext/commands/bot.py", line 1350, in invoke
    await ctx.command.invoke(ctx)
  File "/Users/manideepghanta/Downloads/Discord_Bot/discord_bot/lib/python3.12/site-packages/discord/ext/commands/core.py", line 1029, in invoke
    await injected(*ctx.args, **ctx.kwargs)  # type: ignore
    ^^^^^^^^^^^^^^^^^^^^^^^^^^^^^^^^^^^^^^^
  File "/Users/manideepghanta/Downloads/Discord_Bot/discord_bot/lib/python3.12/site-packages/discord/ext/commands/core.py", line 244, in wrapped
    raise CommandInvokeError(exc) from exc
discord.ext.commands.errors.CommandInvokeError: Command raised an exception: TypeError: Embed.__init__() got an unexpected keyword argument 'file'
2024-05-19 23:14:50,503 - INFO - logging in using static token
2024-05-19 23:14:52,388 - INFO - Shard ID None has connected to Gateway (Session ID: da21da5cbe0edf3f3408dd9bc435be83).
